{"trial_id": "00", "hyperparameters": {"space": [{"class_name": "Int", "config": {"name": "filters", "default": null, "conditions": [], "min_value": 32, "max_value": 128, "step": 32, "sampling": "linear"}}, {"class_name": "Choice", "config": {"name": "kernel_size", "default": 2, "conditions": [], "values": [2, 3, 4], "ordered": true}}, {"class_name": "Float", "config": {"name": "learning_rate", "default": 0.0001, "conditions": [], "min_value": 0.0001, "max_value": 0.01, "step": null, "sampling": "log"}}], "values": {"filters": 96, "kernel_size": 4, "learning_rate": 0.0019272521621405724}}, "metrics": {"metrics": {}}, "score": null, "best_step": 0, "status": "FAILED", "message": "Traceback (most recent call last):\n  File \"/Users/Lin/anaconda3/lib/python3.11/site-packages/keras_tuner/src/engine/base_tuner.py\", line 274, in _try_run_and_update_trial\n    self._run_and_update_trial(trial, *fit_args, **fit_kwargs)\n  File \"/Users/Lin/anaconda3/lib/python3.11/site-packages/keras_tuner/src/engine/base_tuner.py\", line 239, in _run_and_update_trial\n    results = self.run_trial(trial, *fit_args, **fit_kwargs)\n              ^^^^^^^^^^^^^^^^^^^^^^^^^^^^^^^^^^^^^^^^^^^^^^\n  File \"/Users/Lin/anaconda3/lib/python3.11/site-packages/keras_tuner/src/engine/tuner.py\", line 314, in run_trial\n    obj_value = self._build_and_fit_model(trial, *args, **copied_kwargs)\n                ^^^^^^^^^^^^^^^^^^^^^^^^^^^^^^^^^^^^^^^^^^^^^^^^^^^^^^^^\n  File \"/Users/Lin/anaconda3/lib/python3.11/site-packages/keras_tuner/src/engine/tuner.py\", line 233, in _build_and_fit_model\n    results = self.hypermodel.fit(hp, model, *args, **kwargs)\n              ^^^^^^^^^^^^^^^^^^^^^^^^^^^^^^^^^^^^^^^^^^^^^^^\n  File \"/Users/Lin/anaconda3/lib/python3.11/site-packages/keras_tuner/src/engine/hypermodel.py\", line 149, in fit\n    return model.fit(*args, **kwargs)\n           ^^^^^^^^^^^^^^^^^^^^^^^^^^\n  File \"/Users/Lin/anaconda3/lib/python3.11/site-packages/keras/src/utils/traceback_utils.py\", line 70, in error_handler\n    raise e.with_traceback(filtered_tb) from None\n  File \"/var/folders/2j/k_c_x4ps7n352tzdqvckkvb80000gn/T/__autograph_generated_fileln18xs5g.py\", line 18, in tf__train_function\n    raise\nValueError: in user code:\n\n    File \"/Users/Lin/anaconda3/lib/python3.11/site-packages/keras/src/engine/training.py\", line 1401, in train_function  *\n        return step_function(self, iterator)\n    File \"/Users/Lin/anaconda3/lib/python3.11/site-packages/keras/src/engine/training.py\", line 1384, in step_function  **\n        outputs = model.distribute_strategy.run(run_step, args=(data,))\n    File \"/Users/Lin/anaconda3/lib/python3.11/site-packages/keras/src/engine/training.py\", line 1373, in run_step  **\n        outputs = model.train_step(data)\n    File \"/Users/Lin/anaconda3/lib/python3.11/site-packages/keras/src/engine/training.py\", line 1151, in train_step\n        loss = self.compute_loss(x, y, y_pred, sample_weight)\n    File \"/Users/Lin/anaconda3/lib/python3.11/site-packages/keras/src/engine/training.py\", line 1209, in compute_loss\n        return self.compiled_loss(\n    File \"/Users/Lin/anaconda3/lib/python3.11/site-packages/keras/src/engine/compile_utils.py\", line 277, in __call__\n        loss_value = loss_obj(y_t, y_p, sample_weight=sw)\n    File \"/Users/Lin/anaconda3/lib/python3.11/site-packages/keras/src/losses.py\", line 143, in __call__\n        losses = call_fn(y_true, y_pred)\n    File \"/Users/Lin/anaconda3/lib/python3.11/site-packages/keras/src/losses.py\", line 270, in call  **\n        return ag_fn(y_true, y_pred, **self._fn_kwargs)\n    File \"/Users/Lin/anaconda3/lib/python3.11/site-packages/keras/src/losses.py\", line 2221, in categorical_crossentropy\n        return backend.categorical_crossentropy(\n    File \"/Users/Lin/anaconda3/lib/python3.11/site-packages/keras/src/backend.py\", line 5573, in categorical_crossentropy\n        target.shape.assert_is_compatible_with(output.shape)\n\n    ValueError: Shapes (None, 10) and (None, 45, 10) are incompatible\n\n"}